Workbook
Name skill_names: skill_list!$A$1:$A$166

Sheet README
A1: SEAGAS gold annotation - annotator A
A2: Read the JD, then go down to the table. Mark every pre-filled row keep = Y (correct, fix the cells if needed) or N (wrong). Add missing skills on the empty rows with keep = Y. Yellow rows still need a Y or N.
A3: Follow data/jd_dataset/gold/ANNOTATION_GUIDE.md (what counts as a skill, importance cues).
A4: skill_name: pick a canonical name from the drop-down, or type NEW: <term> (click Yes on the warning).
A5: evidence_text: copy the shortest phrase from the JD text. End it with ? if unsure about importance.
A6: One row per skill per JD. Do not rename sheets or move the table header.
A8: jd_ref | B8: role | C8: title | D8: keep = Y | E8: still to review
A9: JD-CE-0001 | B9: CLOUD_ENGINEER | C9: IT Infra & Cloud Intern | D9: =COUNTIF('JD-CE-0001'!$D$34:$D$77,"Y") | E9: =COUNTIFS('JD-CE-0001'!$A$34:$A$77,"<>",'JD-CE-0001'!$D$34:$D$77,"")
A10: JD-CE-0002 | B10: CLOUD_ENGINEER | C10: Internship - Cloud Infrastructure End User Computing | D10: =COUNTIF('JD-CE-0002'!$D$26:$D$65,"Y") | E10: =COUNTIFS('JD-CE-0002'!$A$26:$A$65,"<>",'JD-CE-0002'!$D$26:$D$65,"")
A11: JD-CE-0003 | B11: CLOUD_ENGINEER | C11: Junior Cloud Engineer | D11: =COUNTIF('JD-CE-0003'!$D$76:$D$129,"Y") | E11: =COUNTIFS('JD-CE-0003'!$A$76:$A$129,"<>",'JD-CE-0003'!$D$76:$D$129,"")
A12: JD-CE-0004 | B12: CLOUD_ENGINEER | C12: Junior System Administrator | D12: =COUNTIF('JD-CE-0004'!$D$17:$D$50,"Y") | E12: =COUNTIFS('JD-CE-0004'!$A$17:$A$50,"<>",'JD-CE-0004'!$D$17:$D$50,"")
A13: JD-CE-0005 | B13: CLOUD_ENGINEER | C13: Internship - IT (Cybersecurity & System Administration) | D13: =COUNTIF('JD-CE-0005'!$D$16:$D$46,"Y") | E13: =COUNTIFS('JD-CE-0005'!$A$16:$A$46,"<>",'JD-CE-0005'!$D$16:$D$46,"")
A14: JD-CE-0006 | B14: CLOUD_ENGINEER | C14: Cloud Delivery Support Engineer | D14: =COUNTIF('JD-CE-0006'!$D$37:$D$73,"Y") | E14: =COUNTIFS('JD-CE-0006'!$A$37:$A$73,"<>",'JD-CE-0006'!$D$37:$D$73,"")
A15: JD-CE-0007 | B15: CLOUD_ENGINEER | C15: Specialist - Junior DevOps Engineer | D15: =COUNTIF('JD-CE-0007'!$D$37:$D$71,"Y") | E15: =COUNTIFS('JD-CE-0007'!$A$37:$A$71,"<>",'JD-CE-0007'!$D$37:$D$71,"")
A16: JD-CE-0008 | B16: CLOUD_ENGINEER | C16: Cloud Systems Engineer | D16: =COUNTIF('JD-CE-0008'!$D$51:$D$92,"Y") | E16: =COUNTIFS('JD-CE-0008'!$A$51:$A$92,"<>",'JD-CE-0008'!$D$51:$D$92,"")
A17: JD-CE-0009 | B17: CLOUD_ENGINEER | C17: IT Intern | D17: =COUNTIF('JD-CE-0009'!$D$21:$D$57,"Y") | E17: =COUNTIFS('JD-CE-0009'!$A$21:$A$57,"<>",'JD-CE-0009'!$D$21:$D$57,"")
A18: JD-CE-0010 | B18: CLOUD_ENGINEER | C18: Cloud and IT Operation Intern (2026 Intake) | D18: =COUNTIF('JD-CE-0010'!$D$42:$D$85,"Y") | E18: =COUNTIFS('JD-CE-0010'!$A$42:$A$85,"<>",'JD-CE-0010'!$D$42:$D$85,"")
A19: JD-CY-0001 | B19: CYBER_ANALYST | C19: Internship - Technical Support Engineer | D19: =COUNTIF('JD-CY-0001'!$D$33:$D$66,"Y") | E19: =COUNTIFS('JD-CY-0001'!$A$33:$A$66,"<>",'JD-CY-0001'!$D$33:$D$66,"")
A20: JD-CY-0002 | B20: CYBER_ANALYST | C20: Security Operations Center (SOC) Analyst | D20: =COUNTIF('JD-CY-0002'!$D$49:$D$89,"Y") | E20: =COUNTIFS('JD-CY-0002'!$A$49:$A$89,"<>",'JD-CY-0002'!$D$49:$D$89,"")
A21: JD-CY-0003 | B21: CYBER_ANALYST | C21: PENETRATING TESTING INTERN | D21: =COUNTIF('JD-CY-0003'!$D$26:$D$63,"Y") | E21: =COUNTIFS('JD-CY-0003'!$A$26:$A$63,"<>",'JD-CY-0003'!$D$26:$D$63,"")
A22: JD-CY-0004 | B22: CYBER_ANALYST | C22: Junior Incident Responder, Malaysia | D22: =COUNTIF('JD-CY-0004'!$D$52:$D$88,"Y") | E22: =COUNTIFS('JD-CY-0004'!$A$52:$A$88,"<>",'JD-CY-0004'!$D$52:$D$88,"")
A23: JD-CY-0005 | B23: CYBER_ANALYST | C23: L1 Security Analyst | D23: =COUNTIF('JD-CY-0005'!$D$32:$D$66,"Y") | E23: =COUNTIFS('JD-CY-0005'!$A$32:$A$66,"<>",'JD-CY-0005'!$D$32:$D$66,"")
A24: JD-CY-0006 | B24: CYBER_ANALYST | C24: Junior Cyber Security Analyst | D24: =COUNTIF('JD-CY-0006'!$D$30:$D$64,"Y") | E24: =COUNTIFS('JD-CY-0006'!$A$30:$A$64,"<>",'JD-CY-0006'!$D$30:$D$64,"")
A25: JD-CY-0007 | B25: CYBER_ANALYST | C25: Security Analyst | D25: =COUNTIF('JD-CY-0007'!$D$31:$D$69,"Y") | E25: =COUNTIFS('JD-CY-0007'!$A$31:$A$69,"<>",'JD-CY-0007'!$D$31:$D$69,"")
A26: JD-CY-0008 | B26: CYBER_ANALYST | C26: Internship for Cyber Security Students - RM2,000 for Top Students | D26: =COUNTIF('JD-CY-0008'!$D$22:$D$53,"Y") | E26: =COUNTIFS('JD-CY-0008'!$A$22:$A$53,"<>",'JD-CY-0008'!$D$22:$D$53,"")
A27: JD-CY-0009 | B27: CYBER_ANALYST | C27: IT Intern | D27: =COUNTIF('JD-CY-0009'!$D$30:$D$64,"Y") | E27: =COUNTIFS('JD-CY-0009'!$A$30:$A$64,"<>",'JD-CY-0009'!$D$30:$D$64,"")
A28: JD-CY-0010 | B28: CYBER_ANALYST | C28: Cybersecurity Trainee | D28: =COUNTIF('JD-CY-0010'!$D$27:$D$67,"Y") | E28: =COUNTIFS('JD-CY-0010'!$A$27:$A$67,"<>",'JD-CY-0010'!$D$27:$D$67,"")
A29: JD-DA-0001 | B29: DATA_ANALYST | C29: Business Data Analyst – AI Tools & Growth | D29: =COUNTIF('JD-DA-0001'!$D$35:$D$71,"Y") | E29: =COUNTIFS('JD-DA-0001'!$A$35:$A$71,"<>",'JD-DA-0001'!$D$35:$D$71,"")
A30: JD-DA-0002 | B30: DATA_ANALYST | C30: Digital & Automation Intern | D30: =COUNTIF('JD-DA-0002'!$D$34:$D$70,"Y") | E30: =COUNTIFS('JD-DA-0002'!$A$34:$A$70,"<>",'JD-DA-0002'!$D$34:$D$70,"")
A31: JD-DA-0003 | B31: DATA_ANALYST | C31: Data Analyst (Fresh Graduate) | D31: =COUNTIF('JD-DA-0003'!$D$34:$D$77,"Y") | E31: =COUNTIFS('JD-DA-0003'!$A$34:$A$77,"<>",'JD-DA-0003'!$D$34:$D$77,"")
A32: JD-DA-0004 | B32: DATA_ANALYST | C32: Data Analyst Intern | D32: =COUNTIF('JD-DA-0004'!$D$29:$D$67,"Y") | E32: =COUNTIFS('JD-DA-0004'!$A$29:$A$67,"<>",'JD-DA-0004'!$D$29:$D$67,"")
A33: JD-DA-0005 | B33: DATA_ANALYST | C33: Data Analyst | D33: =COUNTIF('JD-DA-0005'!$D$29:$D$63,"Y") | E33: =COUNTIFS('JD-DA-0005'!$A$29:$A$63,"<>",'JD-DA-0005'!$D$29:$D$63,"")
A34: JD-DA-0006 | B34: DATA_ANALYST | C34: Data Management Assistant | D34: =COUNTIF('JD-DA-0006'!$D$69:$D$109,"Y") | E34: =COUNTIFS('JD-DA-0006'!$A$69:$A$109,"<>",'JD-DA-0006'!$D$69:$D$109,"")
A35: JD-DA-0007 | B35: DATA_ANALYST | C35: DATA ANALYST (INTERNSHIP) | D35: =COUNTIF('JD-DA-0007'!$D$28:$D$60,"Y") | E35: =COUNTIFS('JD-DA-0007'!$A$28:$A$60,"<>",'JD-DA-0007'!$D$28:$D$60,"")
A36: JD-DA-0008 | B36: DATA_ANALYST | C36: Data Analyst (Fresh Graduate Opportunity) | D36: =COUNTIF('JD-DA-0008'!$D$26:$D$65,"Y") | E36: =COUNTIFS('JD-DA-0008'!$A$26:$A$65,"<>",'JD-DA-0008'!$D$26:$D$65,"")
A37: JD-DA-0010 | B37: DATA_ANALYST | C37: Business Intelligence (BI) Intern | D37: =COUNTIF('JD-DA-0010'!$D$32:$D$70,"Y") | E37: =COUNTIFS('JD-DA-0010'!$A$32:$A$70,"<>",'JD-DA-0010'!$D$32:$D$70,"")
A38: JD-DA-0011 | B38: DATA_ANALYST | C38: JUNIOR DATA ANALYST – MANUFACTURING SYSTEMS & PLANNING | D38: =COUNTIF('JD-DA-0011'!$D$61:$D$97,"Y") | E38: =COUNTIFS('JD-DA-0011'!$A$61:$A$97,"<>",'JD-DA-0011'!$D$61:$D$97,"")
A39: JD-DS-0001 | B39: DATA_SCIENTIST | C39: Data Science Intern | D39: =COUNTIF('JD-DS-0001'!$D$34:$D$73,"Y") | E39: =COUNTIFS('JD-DS-0001'!$A$34:$A$73,"<>",'JD-DS-0001'!$D$34:$D$73,"")
A40: JD-DS-0002 | B40: DATA_SCIENTIST | C40: Data Science & AI Internship | D40: =COUNTIF('JD-DS-0002'!$D$33:$D$67,"Y") | E40: =COUNTIFS('JD-DS-0002'!$A$33:$A$67,"<>",'JD-DS-0002'!$D$33:$D$67,"")
A41: JD-DS-0003 | B41: DATA_SCIENTIST | C41: AI Intern – Computer Vision & Multimodal RAG | D41: =COUNTIF('JD-DS-0003'!$D$79:$D$128,"Y") | E41: =COUNTIFS('JD-DS-0003'!$A$79:$A$128,"<>",'JD-DS-0003'!$D$79:$D$128,"")
...

Sheet JD-CE-0001
A1: JD-CE-0001 | CLOUD_ENGINEER | IT Infra & Cloud Intern (entry)
A2: Read the JD, then go down to the table. Mark every pre-filled row keep = Y (correct, fix the cells if needed) or N (wrong). Add missing skills on the empty rows with keep = Y. Yellow rows still need a Y or N.
A3: Go to the label table
A4: Job description
A5: About the role
A7: This is an infrastructure support role assisting the Infrastructure team with IT infrastructure setup, configuration, monitoring and troubleshooting. You will support Microsoft Azure infrastructure activities, including virtual machines, virtual networks, storage and resource monitoring, under the guidance of senior engineers.
A9: Key responsibilities
A11: * Assist the Infrastructure team with basic IT infrastructure setup, configuration, monitoring and troubleshooting
A12: * Support Microsoft Azure infrastructure activities, including virtual machines, virtual networks, storage and resource monitoring, under the guidance of senior engineers
A13: * Assist with network troubleshooting, including IP addressing, DNS, connectivity and basic routing concepts
A14: * Support Windows Server and/or Linux system administration tasks
A15: * Assist in monitoring infrastructure performance, reviewing alerts and documenting incidents
... A31: * Good communication skills and attention to detail
A33: skill_name | B33: importance | C33: evidence_text | D33: keep | E33: note
A34: Monitoring & Observability | B34: required | C34: This is an infrastructure support role assisting the Infrastructure team with IT infrastructure setup, configuration, monitoring and troubleshooting | D34: Y
A35: Problem Solving | B35: required | C35: Good analytical and problem-solving skills | D35: Y
A36: Azure | B36: required | C36: You will support Microsoft Azure infrastructure activities, including virtual machines, virtual networks, storage and resource monitoring, under the guidance of senior engineers | D36: Y
A37: Networking | B37: required | C37: * Assist with network troubleshooting, including IP addressing, DNS, connectivity and basic routing concepts | D37: Y
A38: Windows Server | B38: required | C38: * Support Windows Server and/or Linux system administration tasks | D38: Y
A39: Linux | B39: required | C39: * Support Windows Server and/or Linux system administration tasks | D39: Y
A40: Documentation | B40: required | C40: * Prepare and maintain technical documentation, configuration records and troubleshooting guides | D40: Y
A41: Identity & Access Management | B41: required | C41: * Learn and follow IT security practices, access control procedures and infrastructure management standards | D41: N
A42: Cloud Computing | B42: required | C42: Support Microsoft Azure infrastructure activities | D42: Y
A43: PowerShell | B43: bonus | C43: * Familiarity with PowerShell, Bash, scripting or infrastructure monitoring tools is a plus | D43: Y
A44: Bash | B44: bonus | C44: * Familiarity with PowerShell, Bash, scripting or infrastructure monitoring tools is a plus | D44: Y
A45: Self-Motivation | B45: required | C45: * Willingness to learn, take initiative and work collaboratively with the technical team | D45: Y
... A48: Teamwork | B48: required | C48: work collaboratively with the technical team | D48: Y
A49: Cybersecurity | B49: preferred | C49: Learn and follow IT security practices | D49: Y | E49: '?' resolved, preferred; A/B resolution, AI-assisted adjudication 2026-10-29, see resolution.xlsx
A50: NEW: Virtualisation | B50: bonus | C50: virtual machines or networking technologies is an advantage | D50: Y
A51: Identity & Access Management | B51: preferred | C51: Learn and follow IT security practices, access control procedures | D51: Y | E51: added from B; A/B resolution, AI-assisted adjudication 2026-10-29, see resolution.xlsx

Sheet JD-CE-0002
A1: JD-CE-0002 | CLOUD_ENGINEER | Internship - Cloud Infrastructure End User Computing (entry)
A2: Read the JD, then go down to the table. Mark every pre-filled row keep = Y (correct, fix the cells if needed) or N (wrong). Add missing skills on the empty rows with keep = Y. Yellow rows still need a Y or N.
A3: Go to the label table
A4: Job description
A5: Responsibilities
A7: * Provide first-level technical support for hardware, software and network issues, ensuring prompt resolution and positive user experience.
A8: * Diagnosing and resolving IT incidents in line with organizational standards and best practices.
A9: * Support daily operations through IT asset management, inventory tracking and administration of hardware, software and infrastructure components.
A10: * Maintain accurate and up-to-date documentation of IT systems, configurations, processes and procedures to support transparency and knowledge sharing.
A11: * Assist in designing, developing and implementing new or improved systems and workflows to enhance operational efficiency.
A12: * Process and track IT-related invoices, telecommunications bills, software subscriptions, maintenance contracts and supporting records.
A13: * Support the testing and validation of new systems, applications and technologies to ensure quality and business alignment.
... A23: * Familiarity with public cloud platforms (AWS, Azure, GCP), UiPath (RPA) and programming or database technologies such as SQL is an advantage.
A25: skill_name | B25: importance | C25: evidence_text | D25: keep | E25: note
A26: UI/UX Design | B26: required | C26: * Provide first-level technical support for hardware, software and network issues, ensuring prompt resolution and positive user experience | D26: N
A27: Documentation | B27: required | C27: * Maintain accurate and up-to-date documentation of IT systems, configurations, processes and procedures to support transparency and knowledge sharing | D27: Y
A28: Generative AI | B28: required | C28: * Research, evaluate and introduce emerging technologies and solutions, including Generative AI, automation and robotics to drive organizational improvement | D28: Y
A29: Communication | B29: required | C29: * Strong communication and interpersonal abilities | D29: Y
A30: Time Management | B30: required | C30: * Effective time management and problem-solving skills | D30: Y
A31: Cloud Computing | B31: bonus | C31: * Familiarity with public cloud platforms (AWS, Azure, GCP), UiPath (RPA) and programming or database technologies such as SQL is an advantage | D31: Y
A32: AWS | B32: bonus | C32: * Familiarity with public cloud platforms (AWS, Azure, GCP), UiPath (RPA) and programming or database technologies such as SQL is an advantage | D32: Y
A33: Azure | B33: bonus | C33: * Familiarity with public cloud platforms (AWS, Azure, GCP), UiPath (RPA) and programming or database technologies such as SQL is an advantage | D33: Y
A34: GCP | B34: bonus | C34: * Familiarity with public cloud platforms (AWS, Azure, GCP), UiPath (RPA) and programming or database technologies such as SQL is an advantage | D34: Y
A35: SQL | B35: bonus | C35: * Familiarity with public cloud platforms (AWS, Azure, GCP), UiPath (RPA) and programming or database technologies such as SQL is an advantage | D35: Y
A36: Interpersonal Skills | B36: required | C36: Strong communication and interpersonal abilities. | D36: Y
A37: Problem Solving | B37: required | C37: Effective time management and problem-solving skills. | D37: Y
... A45: NEW: IT Support | B45: required | C45: Provide first-level technical support for hardware, software and network issues | D45: Y
A46: NEW: UiPath | B46: bonus | C46: UiPath (RPA) | D46: Y | E46: added from B; A/B resolution, AI-assisted adjudication 2026-10-29, see resolution.xlsx
A47: NEW: IT Asset Management | B47: required | C47: IT asset management, inventory tracking | D47: Y | E47: added from B; A/B resolution, AI-assisted adjudication 2026-10-29, see resolution.xlsx

Sheet JD-CE-0003
A1: JD-CE-0003 | CLOUD_ENGINEER | Junior Cloud Engineer (junior)
A2: Read the JD, then go down to the table. Mark every pre-filled row keep = Y (correct, fix the cells if needed) or N (wrong). Add missing skills on the empty rows with keep = Y. Yellow rows still need a Y or N.
A3: Go to the label table
A4: Job description
A5: Key Responsibilities
A7: * Build, deploy and maintain the cloud infrastructure that runs our own platforms and our clients’ hosted environments, working to designs set by senior engineers and architects.
A8: * Run day-to-day operations across cloud and on-premises environments — provisioning, patching, monitoring, backup and incident response.
A9: * Take part in migration and deployment projects, from environment build through UAT to go-live support.
A10: * Document what you build: configurations, runbooks, network diagrams and as-built records.
A11: * Learn the platform and the business behind it and grow into owning environments of your own.
A13: Cloud Infrastructure
A15: * Provision and configure compute, storage, networking and identity services on at least one major cloud platform (AWS, Azure or Google Cloud).
... A73: * Occasional onsite work at data centres and client premises, including out-of-hours cutovers and DR drills.
A75: skill_name | B75: importance | C75: evidence_text | D75: keep | E75: note
A76: Cloud Computing | B76: required | C76: * Build, deploy and maintain the cloud infrastructure that runs our own platforms and our clients’ hosted environments, working to designs set by senior engineers and architects | D76: Y
A77: Monitoring & Observability | B77: required | C77: * Run day-to-day operations across cloud and on-premises environments — provisioning, patching, monitoring, backup and incident response | D77: Y
A78: Incident Response | B78: required | C78: * Run day-to-day operations across cloud and on-premises environments — provisioning, patching, monitoring, backup and incident response | D78: Y
A79: Networking | B79: required | C79: * Provision and configure compute, storage, networking and identity services on at least one major cloud platform (AWS, Azure or Google Cloud) | D79: Y
A80: AWS | B80: required | C80: * Provision and configure compute, storage, networking and identity services on at least one major cloud platform (AWS, Azure or Google Cloud) | D80: Y
A81: Azure | B81: required | C81: * Provision and configure compute, storage, networking and identity services on at least one major cloud platform (AWS, Azure or Google Cloud) | D81: Y
A82: GCP | B82: required | C82: * Provision and configure compute, storage, networking and identity services on at least one major cloud platform (AWS, Azure or Google Cloud) | D82: Y
A83: VPN | B83: required | C83: * Support hybrid setups that link cloud environments to on-premises data centres over VPN or dedicated circuits | D83: Y
A84: Docker | B84: required | C84: * Build and maintain container images and run workloads under Docker or a comparable runtime | D84: Y
A85: Kubernetes | B85: required | C85: * Deploy and support applications on Kubernetes or a managed equivalent (EKS, AKS, GKE) — deployments, services, ingress, config maps, secrets and persistent volumes | D85: Y
A86: CI/CD | B86: required | C86: * Work with CI/CD pipelines to move builds through development, staging and production | D86: Y
A87: Linux | B87: required | C87: * Administer Linux servers (RHEL, Rocky, Ubuntu or equivalent) — users and permissions, packages, services, storage, OS and kernel patching, and shell scripting | D87: Y
... A107: NEW: Infrastructure as Code | B107: bonus | C107: Infrastructure as code | D107: Y

Sheet JD-CE-0004
A1: JD-CE-0004 | CLOUD_ENGINEER | Junior System Administrator (junior)
A2: Read the JD, then go down to the table. Mark every pre-filled row keep = Y (correct, fix the cells if needed) or N (wrong). Add missing skills on the empty rows with keep = Y. Yellow rows still need a Y or N.
A3: Go to the label table
A4: Job description
A5: Are you passionate about high-performance computing, digging deep into Linux systems, and working with cutting-edge infrastructure? Looking for a fast-paced environment where your skills directly support groundbreaking work across the globe?
A6: [COMPANY] is looking for a Junior System Administrator to join our global IT operations team. You'll be hands-on with our high-performance computing (HPC) infrastructure, working on everything from compute clusters to high-speed networks and large-scale storage systems. If you enjoy diving into Linux internals, writing and running bash scripts, and supporting users who rely on you to keep things running smoothly, we want to hear from you.
A8: Requirements
A10: * A Diploma/ Bachelor's in Computer Science, Computer Engineering, or equivalent.
A11: * Experience with Linux (any flavour!)
A12: * Hands-on homelab experience would be highly desirable
A13: * Excellent communication skills; fluent in written and spoken English.
A14: * The ability to multitask and be agile
A16: skill_name | B16: importance | C16: evidence_text | D16: keep | E16: note
A17: Linux | B17: required | C17: Are you passionate about high-performance computing, digging deep into Linux systems, and working with cutting-edge infrastructure? Looking for a fast-paced environment where your skills directly support groundbreaking work across the globe? | D17: Y
A18: Bash | B18: required | C18: If you enjoy diving into Linux internals, writing and running bash scripts, and supporting users who rely on you to keep things running smoothly, we want to hear from you | D18: Y
A19: Communication | B19: required | C19: * Excellent communication skills | D19: Y
A20: Agile / Scrum | B20: required | C20: * The ability to multitask and be agile | D20: N
A21: NEW: High-Performance Computing | B21: required | C21: high-performance computing (HPC) infrastructure | D21: Y
A22: Networking | B22: required | C22: high-speed networks | D22: Y
A23: Time Management | B23: required | C23: The ability to multitask? | D23: Y

Sheet JD-CE-0005
A1: JD-CE-0005 | CLOUD_ENGINEER | Internship - IT (Cybersecurity & System Administration) (entry)
A2: Read the JD, then go down to the table. Mark every pre-filled row keep = Y (correct, fix the cells if needed) or N (wrong). Add missing skills on the empty rows with keep = Y. Yellow rows still need a Y or N.
A3: Go to the label table
A4: Job description
A5: Requirements
A7: * Open to degree students pursuing studies in Computer Science, Information Technology, or any other relevant discipline
A8: * Interested to pursue internship opportunity in Cybersecurity or System Administraion field
A9: * For local students only
A10: * A minimum of 6 months placement is required
A11: * A good command of English
A13: Perks and benefits: Medical; Miscellaneous allowance; Loans; Dental; Vision; Employer EPF Contribution of 16%
A15: skill_name | B15: importance | C15: evidence_text | D15: keep | E15: note
A16: Cybersecurity | B16: required | C16: * Interested to pursue internship opportunity in Cybersecurity or System Administraion field | D16: N

Sheet JD-CE-0006
A1: JD-CE-0006 | CLOUD_ENGINEER | Cloud Delivery Support Engineer (entry)
A2: Read the JD, then go down to the table. Mark every pre-filled row keep = Y (correct, fix the cells if needed) or N (wrong). Add missing skills on the empty rows with keep = Y. Yellow rows still need a Y or N.
A3: Go to the label table
A4: Job description
A5: Cloud Delivery Support Engineer (Fresh graduate)
A7: Employment: 1-Year Contract, renewable annually; conversion to Permanent in the third year
A8: Work Mode: Hybrid, Shift-based
A9: Shift: 9:00 AM–6:00 PM / 5:00 PM–12:00 AM
A10: Rest Days: 2 rest days per week, scheduled based on roster and not fixed on Saturday or Sunday
A12: Responsibilities
A14: * Support cloud service delivery, including account provisioning, service activation, configuration and deployment.
A15: * Provide L1 technical support and basic troubleshooting for cloud-related issues.
... A34: * AWS, Azure, Alibaba Cloud or Tencent Cloud knowledge or certification is an advantage.
A36: skill_name | B36: importance | C36: evidence_text | D36: keep | E36: note
A37: Problem Solving | B37: required | C37: * Provide L1 technical support and basic troubleshooting for cloud-related issues | D37: Y
A38: Customer Focus | B38: required | C38: * Handle customer service requests, incidents and technical enquiries, with proper escalation when required | D38: Y
A39: Cloud Computing | B39: required | C39: * Support multiple cloud platforms, including AWS, Azure, Alibaba Cloud and Tencent Cloud | D39: Y
A40: AWS | B40: required | C40: * Support multiple cloud platforms, including AWS, Azure, Alibaba Cloud and Tencent Cloud | D40: Y
A41: Azure | B41: required | C41: * Support multiple cloud platforms, including AWS, Azure, Alibaba Cloud and Tencent Cloud | D41: Y
A42: Networking | B42: required | C42: * Basic understanding of cloud infrastructure, networking, virtual machines and cloud services | D42: Y
A43: Communication | B43: required | C43: * Proficiency in Mandarin is mandatory, as the role requires direct communication with Mandarin-speaking clients | D43: Y
A44: Excel | B44: required | C44: Proficient in Excel and Google Sheets. | D44: Y
A45: NEW: Google Sheets | B45: required | C45: Proficient in Excel and Google Sheets. | D45: Y
A46: Time Management | B46: required | C46: Able to manage multiple tasks in a fast-paced environment. | D46: Y
A47: Stakeholder Communication | B47: required | C47: Coordinate with Technical, Sales and Procurement teams | D47: Y
A48: NEW: Alibaba Cloud | B48: required | C48: Alibaba Cloud | D48: Y
... A50: NEW: IT Support | B50: required | C50: Provide L1 technical support and basic troubleshooting | D50: Y

Sheet JD-CE-0007
A1: JD-CE-0007 | CLOUD_ENGINEER | Specialist - Junior DevOps Engineer (junior)
A2: Read the JD, then go down to the table. Mark every pre-filled row keep = Y (correct, fix the cells if needed) or N (wrong). Add missing skills on the empty rows with keep = Y. Yellow rows still need a Y or N.
A3: Go to the label table
A4: Job description
A5: Responsibilities of the Role
A7: We are looking for an enthusiastic DevOps Engineer who has the following qualities and responsibilities:
A9: Application support
A11: * Resolve issues
A12: * Perform site performance monitoring to determine system performance bottlenecks.
A13: * Manage operation day-to-day technical issues.
A15: DevOps tasks
A17: * Support the application CI/CD pipeline for promoting software into higher environments.
... A34: Perks and benefits: Performance related bonus for confirmed staff; Annual Leave 15 days; Medical Leave 14 days; Medical and hospitalization coverage
A36: skill_name | B36: importance | C36: evidence_text | D36: keep | E36: note
A37: Monitoring & Observability | B37: required | C37: * Perform site performance monitoring to determine system performance bottlenecks | D37: Y
A38: CI/CD | B38: required | C38: * Support the application CI/CD pipeline for promoting software into higher environments | D38: Y
A39: Self-Motivation | B39: required | C39: Proactive learner | D39: Y
A40: Teamwork | B40: required | C40: * Good teamwork | D40: Y
A41: Communication | B41: required | C41: * Good interpersonal and communication skills | D41: Y
A42: Critical Thinking | B42: required | C42: Critical thinker | D42: Y
A43: Problem Solving | B43: required | C43: Critical thinker and problem-solving skills. | D43: Y
A44: Time Management | B44: required | C44: Good time-management skills. | D44: Y
A45: Interpersonal Skills | B45: required | C45: Good interpersonal and communication skills. | D45: Y
A46: Research Skills | B46: required | C46: ability to research and quickly utilize new technologies | D46: Y
A47: NEW: DevOps | B47: required | C47: DevOps tools support | D47: Y

Sheet JD-CE-0008
A1: JD-CE-0008 | CLOUD_ENGINEER | Cloud Systems Engineer (mid)
A2: Read the JD, then go down to the table. Mark every pre-filled row keep = Y (correct, fix the cells if needed) or N (wrong). Add missing skills on the empty rows with keep = Y. Yellow rows still need a Y or N.
A3: Go to the label table
A4: Job description
A5: We are looking for a Cloud System Engineer who is well-versed in private and public cloud infrastructure, Linux server management, along with experience in on-premise to cloud migration.
A6: Responsibilities include implementation, configuration and support of our cloud server infrastructure across South East Asia, as well as planning and execution of migration of on-premise servers and applications to the cloud.
A7: Most tasks will be carried out remotely.
A9: What you will be doing
A11: * Operating and maintaining large scale cloud infrastructure and servers in global data centres
A12: * Working on various Linux server projects alongside multiple departments
A13: * Migrating clients on-premise servers to the cloud via replication or data backups
A14: * Assessing and resolving server and network-related issues escalated by internal and external users
... A48: * Willing to travel (e.g. to server locations for cloud migration)
A50: skill_name | B50: importance | C50: evidence_text | D50: keep | E50: note
A51: Cloud Computing | B51: required | C51: We are looking for a Cloud System Engineer who is well-versed in private and public cloud infrastructure, Linux server management, along with experience in on-premise to cloud migration | D51: Y
A52: Linux | B52: required | C52: We are looking for a Cloud System Engineer who is well-versed in private and public cloud infrastructure, Linux server management, along with experience in on-premise to cloud migration | D52: Y
A53: Self-Motivation | B53: required | C53: Able to work autonomously | D53: Y
A54: Monitoring & Observability | B54: required | C54: * Proactive monitoring of supported cloud instances | D54: Y
A55: Problem Solving | B55: required | C55: Assessing and resolving server and network-related issues | D55: Y
A56: Azure | B56: bonus | C56: Both AWS/Azure/GCP and non-AWS/Azure/GCP cloud experience | D56: Y
A57: Ansible | B57: required | C57: * Automation - Salt, Ansible, Puppet, Chef | D57: Y
A58: AWS | B58: bonus | C58: Both AWS/Azure/GCP and non-AWS/Azure/GCP cloud experience | D58: Y
A59: GCP | B59: bonus | C59: Both AWS/Azure/GCP and non-AWS/Azure/GCP cloud experience | D59: Y
A60: Windows Server | B60: bonus | C60: Experience with Windows Server 2012, 2016, 2019, and Microsoft SQL | D60: Y
A61: NEW: Microsoft SQL Server | B61: bonus | C61: Microsoft SQL | D61: Y
A62: Communication | B62: required | C62: * Excellent written and verbal communication skills (English) | D62: Y
... A69: NEW: OpenStack | B69: bonus | C69: Cloudstack, Openstack, Proxmox VE | D69: Y

Sheet JD-CE-0009
A1: JD-CE-0009 | CLOUD_ENGINEER | IT Intern (entry)
A2: Read the JD, then go down to the table. Mark every pre-filled row keep = Y (correct, fix the cells if needed) or N (wrong). Add missing skills on the empty rows with keep = Y. Yellow rows still need a Y or N.
A3: Go to the label table
A4: Job description
A5: Job Responsibilities
A7: * System Administration: Provide support in managing and overseeing the company’s ticketing platform in coordination with the Operations department
A8: * Technical Support: Assist with troubleshooting procedures and deliver technical guidance whenever necessary
A9: * Resource Management: Systematize, track, and maintain the organization’s IT assets and technical resources
A10: * Directives: Execute specific tasks and projects as designated by the Chief Technology Officer (CTO) or the Head of Department
A12: Job Requirements
A14: * Academic Credentials: Minimum of a Diploma, Advanced/Higher/Graduate Diploma, or a Bachelor’s Degree in Computer Science, Software Engineering, Information Technology, or a similar technical field
A15: * Technical Proficiency: Familiarity with a diverse range of programming languages and frameworks is an added advantage (PHP Laravel, Node.js, React.ks, JavaScript, HTML, CSS, Flutter)
... A18: Perks and benefits: 5 working days a week (9:00 AM – 6:00 PM); 7-minute walk from Taman Perindustrian Puchong LRT station; Basement parking
A20: skill_name | B20: importance | C20: evidence_text | D20: keep | E20: note
A21: Problem Solving | B21: required | C21: * Technical Support: Assist with troubleshooting procedures and deliver technical guidance whenever necessary | D21: Y
A22: PHP | B22: bonus | C22: * Technical Proficiency: Familiarity with a diverse range of programming languages and frameworks is an added advantage (PHP Laravel, Node | D22: Y
A23: Node.js | B23: bonus | C23: * Technical Proficiency: Familiarity with a diverse range of programming languages and frameworks is an added advantage (PHP Laravel, Node.js, React | D23: Y
A24: React | B24: bonus | C24: Familiarity with a diverse range of programming languages and frameworks is an added advantage | D24: Y
A25: JavaScript | B25: bonus | C25: ks, JavaScript, HTML, CSS, Flutter) | D25: Y
A26: HTML | B26: bonus | C26: ks, JavaScript, HTML, CSS, Flutter) | D26: Y
A27: CSS | B27: bonus | C27: ks, JavaScript, HTML, CSS, Flutter) | D27: Y
A28: NEW: Laravel | B28: bonus | C28: PHP Laravel | D28: Y
A29: NEW: Flutter | B29: bonus | C29: Flutter | D29: Y
A30: NEW: IT Support | B30: required | C30: Assist with troubleshooting procedures and deliver technical guidance | D30: Y
A31: NEW: IT Asset Management | B31: required | C31: IT assets and technical resources | D31: Y

Sheet JD-CE-0010
A1: JD-CE-0010 | CLOUD_ENGINEER | Cloud and IT Operation Intern (2026 Intake) (entry)
A2: Read the JD, then go down to the table. Mark every pre-filled row keep = Y (correct, fix the cells if needed) or N (wrong). Add missing skills on the empty rows with keep = Y. Yellow rows still need a Y or N.
A3: Go to the label table
A4: Job description
A5: About the Role
A7: We are looking for passionate Interns to assist our Delivery team in resolving common day-to-day challenges in Enterprise Cloud and ITO Infrastructure (Active Directory, Servers, Storage, Backup, Database, Middleware, Networks etc) services. The Intern would need to be eager to explore new things including elements of AI in helping us improve our services delivery.
A9: Key Responsibilities
A11: * Assist in research and documentation related to AI technologies and their applications in enterprise environments.
A12: * Support infrastructure-related tasks such as monitoring systems, basic troubleshooting, and configuration under supervision.
A13: * Help with endpoint device management (Windows, macOS, mobile devices), including inventory checks and basic setup.
A14: * Participate in testing and validation of AI-driven tools and automation workflows.
A15: * Prepare reports and presentations on findings and progress.
... A39: * Malaysian citizens only
A41: skill_name | B41: importance | C41: evidence_text | D41: keep | E41: note
A42: Identity & Access Management | B42: required | C42: We are looking for passionate Interns to assist our Delivery team in resolving common day-to-day challenges in Enterprise Cloud and ITO Infrastructure (Active Directory, Servers, Storage, Backup, Database, Middleware, Networks etc) services | D42: Y
A43: Documentation | B43: required | C43: * Assist in research and documentation related to AI technologies and their applications in enterprise environments | D43: Y
A44: Monitoring & Observability | B44: required | C44: * Support infrastructure-related tasks such as monitoring systems, basic troubleshooting, and configuration under supervision | D44: Y
A45: Problem Solving | B45: required | C45: * Support infrastructure-related tasks such as monitoring systems, basic troubleshooting, and configuration under supervision | D45: Y
A46: AI Literacy | B46: required | C46: * Basic understanding of AI concepts (e | D46: Y
A47: Machine Learning | B47: required | C47: , machine learning, chatbots, automation) | D47: Y
A48: Linux | B48: preferred | C48: * Familiarity with multiple OS platform (Windows, Unix, Linux, macOS, mobile platforms) | D48: Y
A49: Python | B49: preferred | C49: * Exposure to scripting languages (Python, PowerShell) or interest in learning | D49: Y
A50: PowerShell | B50: preferred | C50: * Exposure to scripting languages (Python, PowerShell) or interest in learning | D50: Y
A51: Cloud Computing | B51: required | C51: * Awareness of cloud platforms (Azure, AWS, or GCP) | D51: Y
A52: Azure | B52: preferred | C52: Awareness of cloud platforms (Azure, AWS, or GCP). | D52: Y
A53: AWS | B53: preferred | C53: Awareness of cloud platforms (Azure, AWS, or GCP). | D53: Y
... A63: NEW: Endpoint Device Management | B63: required | C63: endpoint device management | D63: Y

Sheet JD-CY-0001
A1: JD-CY-0001 | CYBER_ANALYST | Internship - Technical Support Engineer (entry)
A2: Read the JD, then go down to the table. Mark every pre-filled row keep = Y (correct, fix the cells if needed) or N (wrong). Add missing skills on the empty rows with keep = Y. Yellow rows still need a Y or N.
A3: Go to the label table
A4: Job description
A5: Job Description
A7: * The candidate will be assigned to the technical support department and will be trained on providing technical support for the assigned cybersecurity products.
A8: * Work closely with technical support team to learn the technical support operations and assist the team on case management.
A9: * Learn and use the case management tool and phone system to perform support operations.
A10: * Perform any other duties deemed relevant as assigned.
A12: Highlights
A14: * Exposure in cybersecurity products and technologies.
A15: * Learning on how to investigate and troubleshoot cybersecurity products issues.
... A30: * Internship duration is 6 months.
A32: skill_name | B32: importance | C32: evidence_text | D32: keep | E32: note
A33: Cybersecurity | B33: required | C33: Attended courses related to networking and security. | D33: Y
A34: Communication | B34: required | C34: * Improving communication and customer engagement skills through working with customers and users from different Asia Pacific countries and from different levels within a company | D34: Y
A35: Networking | B35: required | C35: Attended courses related to networking and security. | D35: Y
A36: Time Management | B36: required | C36: * Strong organizational and time management skills | D36: Y
A37: Self-Motivation | B37: required | C37: Quick learner and always look for ways to improve own self. | D37: Y
A38: Teamwork | B38: required | C38: Work closely with technical support team | D38: Y
A39: NEW: Organisational Skills | B39: required | C39: Strong organizational and time management skills. | D39: Y
A40: NEW: IT Support | B40: required | C40: providing technical support for the assigned cybersecurity products | D40: Y | E40: renamed; guide rule R1 applied after the A/B resolution (AI-assisted, 2026-10-29)

Sheet JD-CY-0002
A1: JD-CY-0002 | CYBER_ANALYST | Security Operations Center (SOC) Analyst (mid)
A2: Read the JD, then go down to the table. Mark every pre-filled row keep = Y (correct, fix the cells if needed) or N (wrong). Add missing skills on the empty rows with keep = Y. Yellow rows still need a Y or N.
A3: Go to the label table
A4: Job description
A5: Job Responsibility
A7: A passion for research, and uncovering the unknown about internet threats and threat actors.
A9: i) Communication
A11: * The first point of contact for security incident notifications from customers, service desks, IT engineers and administrator during emergencies
A12: * Develop a professional working relationship with fellow analysts.
A14: ii) Monitoring
A16: * General SIEM monitoring, analysis, content development, and maintenance.
A18: iii) Identifying
... A46: * Excellent communication (written and oral) and interpersonal skills
A48: skill_name | B48: importance | C48: evidence_text | D48: keep | E48: note
A49: Communication | B49: required | C49: i) Communication | D49: Y
A50: Monitoring & Observability | B50: required | C50: ii) Monitoring | D50: N
A51: SIEM | B51: required | C51: * General SIEM monitoring, analysis, content development, and maintenance | D51: Y
A52: React | B52: required | C52: * React to security alerts and security events of interest from defense systems like IDS, endpoint protection and other security-related systems | D52: N
A53: Documentation | B53: required | C53: including log retrieval and documentation | D53: Y
A54: Incident Response | B54: required | C54: * Assist in incident response activities such as host triage and retrieval, malware analysis, remote system analysis and remediation efforts | D54: Y
A55: Malware Analysis | B55: required | C55: * Assist in incident response activities such as host triage and retrieval, malware analysis, remote system analysis and remediation efforts | D55: Y
A56: Cybersecurity | B56: required | C56: * Analyze cybersecurity alerts and data for false positive/true positive outcomes while modifying, alerts as needed | D56: Y
A57: Security Operations (SOC) | B57: required | C57: * Ensure the SOC analyst team is providing excellent customer service and support | D57: Y
A58: Customer Focus | B58: required | C58: * Ensure the SOC analyst team is providing excellent customer service and support | D58: Y
A59: Interpersonal Skills | B59: required | C59: * Excellent communication (written and oral) and interpersonal skills | D59: Y
A60: Threat Intelligence | B60: required | C60: uncovering the unknown about internet threats and threat actors | D60: Y
... A65: NEW: Root Cause Analysis | B65: required | C65: Perform Root Cause Analysis of security incidents | D65: Y

Sheet JD-CY-0003
A1: JD-CY-0003 | CYBER_ANALYST | PENETRATING TESTING INTERN (entry)
A2: Read the JD, then go down to the table. Mark every pre-filled row keep = Y (correct, fix the cells if needed) or N (wrong). Add missing skills on the empty rows with keep = Y. Yellow rows still need a Y or N.
A3: Go to the label table
A4: Job description
A5: Key responsibilities
A7: * Assist the Security Assessment team in conducting penetration testing and vulnerability assessments
A8: * Assist with documenting security findings and preparing penetration testing reports
A9: * Support basic security testing of web applications, networks and systems
A10: * Assist in identifying, validating and documenting security vulnerabilities
A11: * Help prepare technical reports and documentation
A12: * Conduct research on vulnerabilities, exploits and cybersecurity tools
A13: * Support other technical tasks assigned by the team
... A23: Perks and benefits: Medical; Miscellaneous allowance; Education support; Dental; Parking; Vision
A25: skill_name | B25: importance | C25: evidence_text | D25: keep | E25: note
A26: Ethical Hacking | B26: required | C26: * Assist the Security Assessment team in conducting penetration testing and vulnerability assessments | D26: Y
A27: Documentation | B27: required | C27: * Help prepare technical reports and documentation | D27: Y
A28: Cybersecurity | B28: required | C28: * Conduct research on vulnerabilities, exploits and cybersecurity tools | D28: Y
A29: Networking | B29: required | C29: * Basic knowledge of networking, operating systems and cybersecurity concepts | D29: Y
A30: Vulnerability Assessment | B30: required | C30: * Interest in penetration testing, ethical hacking and vulnerability assessment | D30: Y
A31: Kali Linux | B31: bonus | C31: * Familiarity with tools such as Kali Linux, Burp Suite or Nmap is an advantage | D31: Y
A32: Burp Suite | B32: bonus | C32: * Familiarity with tools such as Kali Linux, Burp Suite or Nmap is an advantage | D32: Y
A33: Nmap | B33: bonus | C33: * Familiarity with tools such as Kali Linux, Burp Suite or Nmap is an advantage | D33: Y
A34: Problem Solving | B34: required | C34: Good analytical and problem-solving skills | D34: Y
A35: Research Skills | B35: required | C35: Conduct research on vulnerabilities, exploits and cybersecurity tools | D35: Y
A36: Self-Motivation | B36: required | C36: with a willingness to learn | D36: Y
A37: NEW: Web Application Security | B37: required | C37: Support basic security testing of web applications | D37: Y

Sheet JD-CY-0004
A1: JD-CY-0004 | CYBER_ANALYST | Junior Incident Responder, Malaysia (junior)
A2: Read the JD, then go down to the table. Mark every pre-filled row keep = Y (correct, fix the cells if needed) or N (wrong). Add missing skills on the empty rows with keep = Y. Yellow rows still need a Y or N.
A3: Go to the label table
A4: Job description
A5: Your Mission: Junior Incident Responder
A7: As a Junior Incident Responder, you will work alongside senior responders on live engagements — helping clients contain, investigate, and recover from real cyber attacks. This is a delivery-focused role: your job is to do the work, learn the craft, and grow into a fully fledged responder under direct mentorship.
A8: We hire for attitude and aptitude. We don't expect you to have seen everything yet — we expect you to be curious, coachable, and serious about building a career in incident response. The right candidate can demonstrate a genuine interest in IR through their experience, side projects, study, or community involvement, and shows up ready to learn fast in a real-world environment.
A10: Core Responsibilities
A12: Delivery Alongside Senior Responders
A14: * Support senior consultants on active incidents — assisting with containment, evidence collection, forensic analysis, and reporting.
A15: * Acquire and triage forensic artifacts across Windows, Linux, macOS, and cloud environments under the guidance of more experienced team members.
A16: * Analyse logs, endpoint telemetry, network data, and malware artifacts, and contribute findings to investigation timelines.
... A49: Perks and benefits: Paired with senior responders from day one; Hands-on mentorship and structured instructor-led training program
A51: skill_name | B51: importance | C51: evidence_text | D51: keep | E51: note
A52: Incident Response | B52: required | C52: We don't expect you to have seen everything yet — we expect you to be curious, coachable, and serious about building a career in incident response | D52: Y
A53: Linux | B53: required | C53: * Acquire and triage forensic artifacts across Windows, Linux, macOS, and cloud environments under the guidance of more experienced team members | D53: Y
A54: Python | B54: required | C54: * Use scripting (Python, Bash, or PowerShell) to assist with collection, parsing, and automation tasks where useful | D54: Y
A55: Bash | B55: required | C55: * Use scripting (Python, Bash, or PowerShell) to assist with collection, parsing, and automation tasks where useful | D55: Y
A56: PowerShell | B56: required | C56: * Use scripting (Python, Bash, or PowerShell) to assist with collection, parsing, and automation tasks where useful | D56: Y
A57: Cybersecurity | B57: required | C57: * 1+ year of experience in cybersecurity, IT, or an adjacent technical field (e | D57: Y
A58: SIEM | B58: preferred | C58: * Hands-on exposure to EDR, SIEM, or forensic tooling, even in a learning context | D58: Y
A59: Digital Forensics | B59: required | C59: forensic analysis | D59: Y
A60: Log Analysis | B60: required | C60: Analyse logs, endpoint telemetry, network data | D60: Y
A61: Malware Analysis | B61: required | C61: malware artifacts | D61: Y
A62: Documentation | B62: required | C62: Document findings clearly and accurately | D62: Y
A63: Communication | B63: required | C63: communicate professionally with teammates and clients | D63: Y
... A69: NEW: EDR | B69: preferred | C69: Hands-on exposure to EDR, SIEM, or forensic tooling | D69: Y
A70: Cloud Computing | B70: required | C70: Windows, Linux, macOS, and cloud environments | D70: Y | E70: added from B; A/B resolution, AI-assisted adjudication 2026-10-29, see resolution.xlsx
A71: NEW: Chain of Custody | B71: required | C71: chain-of-custody requirements | D71: Y | E71: added from B; A/B resolution, AI-assisted adjudication 2026-10-29, see resolution.xlsx

Sheet JD-CY-0005
A1: JD-CY-0005 | CYBER_ANALYST | L1 Security Analyst (junior)
A2: Read the JD, then go down to the table. Mark every pre-filled row keep = Y (correct, fix the cells if needed) or N (wrong). Add missing skills on the empty rows with keep = Y. Yellow rows still need a Y or N.
A3: Go to the label table
A4: Job description
A5: Key Responsibilities
A7: * Monitor security alerts and logs from various security tools such as SIEM (Security Information and Event Management) systems, firewalls, antivirus, and intrusion detection/prevention systems.
A8: * Investigate and analyze potential security incidents or breaches and escalate as necessary to senior analysts or incident response teams.
A9: * Perform routine security assessments and vulnerability scans to identify and report risks.
A10: * Assist in maintaining and updating security documentation, policies, and procedures.
A11: * Participate in security awareness training programs for employees.
A12: * Support compliance efforts with relevant regulations and standards (e.g., GDPR, HIPAA, PCI-DSS).
A13: * Collaborate with IT teams to implement security controls and mitigate identified risks.
... A29: Perks and benefits: Medical; Miscellaneous allowance; Dental; Sports (e.g. Gym); Parking
A31: skill_name | B31: importance | C31: evidence_text | D31: keep | E31: note
A32: SIEM | B32: required | C32: * Monitor security alerts and logs from various security tools such as SIEM (Security Information and Event Management) systems, firewalls, antivirus, and intrusion detection/prevention systems | D32: Y
A33: Incident Response | B33: required | C33: * Investigate and analyze potential security incidents or breaches and escalate as necessary to senior analysts or incident response teams | D33: Y
A34: Documentation | B34: required | C34: * Assist in maintaining and updating security documentation, policies, and procedures | D34: Y
A35: Cybersecurity | B35: required | C35: * Stay updated with the latest cybersecurity trends, threats, and technologies | D35: Y
A36: Communication | B36: required | C36: * Good communication skills for documenting incidents and collaborating with teams | D36: Y
A37: Vulnerability Assessment | B37: required | C37: Perform routine security assessments and vulnerability scans | D37: Y
A38: Security Frameworks | B38: required | C38: relevant regulations and standards (e.g., GDPR, HIPAA, PCI-DSS) | D38: Y
A39: Networking | B39: required | C39: Basic understanding of network protocols | D39: Y
A40: Problem Solving | B40: required | C40: Strong analytical and problem-solving skills. | D40: Y
A41: Teamwork | B41: required | C41: Collaborate with IT teams to implement security controls | D41: Y
A42: Risk Analysis | B42: required | C42: mitigate identified risks | D42: Y
A43: Log Analysis | B43: required | C43: Monitor security alerts and logs | D43: Y
A44: Security Operations (SOC) | B44: required | C44: Monitor security alerts and logs from various security tools | D44: Y
A45: Firewall Management | B45: required | C45: Monitor security alerts and logs from various security tools such as SIEM (Security Information and Event Management) systems, firewalls | D45: Y | E45: importance preferred -> required (duty); A/B resolution, AI-assisted adjudication 2026-10-29, see resolution.xlsx
A46: NEW: Intrusion Detection/Prevention | B46: required | C46: intrusion detection/prevention systems | D46: Y | E46: renamed (R1); A/B resolution, AI-assisted adjudication 2026-10-29, see resolution.xlsx
A47: NEW: Antivirus | B47: required | C47: antivirus | D47: Y | E47: added from B; A/B resolution, AI-assisted adjudication 2026-10-29, see resolution.xlsx
A48: NEW: Operating Systems | B48: required | C48: Basic understanding of network protocols, operating systems | D48: Y | E48: added from B; A/B resolution, AI-assisted adjudication 2026-10-29, see resolution.xlsx

Sheet JD-CY-0006
A1: JD-CY-0006 | CYBER_ANALYST | Junior Cyber Security Analyst (junior)
A2: Read the JD, then go down to the table. Mark every pre-filled row keep = Y (correct, fix the cells if needed) or N (wrong). Add missing skills on the empty rows with keep = Y. Yellow rows still need a Y or N.
A3: Go to the label table
A4: Job description
A5: Continuous Security Monitoring Execute 24/7
A7: * Continuous monitoring of security events across enterprise infrastructure using SIEM platforms.
A8: * Analyze correlated security alerts to identify active threats, suspicious behaviors, and false positives.
A9: * Maintain baseline awareness of system traffic patterns and flag anomalous volume or connection spikes.
A11: Incident Triage & Tier-2 Escalation Perform
A13: * Initial investigation and scope analysis for confirmed security events and policy violations.
A14: * Document comprehensive triage findings, context, and impact assessments within incident tracking tickets.
A15: * Escalate complex or high-severity threats to L2 SOC Analysts, Incident Response, or Engineering units.
... A27: Perks and benefits: Flexible schedule; Maternity leave
A29: skill_name | B29: importance | C29: evidence_text | D29: keep | E29: note
A30: Security Operations (SOC) | B30: required | C30: Continuous Security Monitoring Execute 24/7 | D30: Y
A31: Monitoring & Observability | B31: required | C31: * Continuous monitoring of security events across enterprise infrastructure using SIEM platforms | D31: N
A32: SIEM | B32: required | C32: * Continuous monitoring of security events across enterprise infrastructure using SIEM platforms | D32: Y
A33: Incident Response | B33: required | C33: * Escalate complex or high-severity threats to L2 SOC Analysts, Incident Response, or Engineering units | D33: Y
A34: Threat Intelligence | B34: required | C34: * Utilize threat intelligence feeds and known Indicators of Compromise (IOCs) for targeted environment queries | D34: Y
A35: Log Analysis | B35: required | C35: Collect, parse, and validate ingestion from multi-vendor sources | D35: Y
A36: Documentation | B36: required | C36: Document comprehensive triage findings | D36: Y
A37: Network Security | B37: required | C37: enterprise network traffic | D37: Y

Sheet JD-CY-0007
A1: JD-CY-0007 | CYBER_ANALYST | Security Analyst (junior)
A2: Read the JD, then go down to the table. Mark every pre-filled row keep = Y (correct, fix the cells if needed) or N (wrong). Add missing skills on the empty rows with keep = Y. Yellow rows still need a Y or N.
A3: Go to the label table
A4: Job description
A5: Key Responsibilities
A7: * Monitor security events and alerts from SIEM tools and other security platforms.
A8: * Perform initial analysis and triage of security incidents based on standard operating procedures (SOPs).
A9: * Escalate verified incidents to L2/L3 analysts or Incident Response team when necessary.
A10: * Document alerts, investigations, and incident handling actions accurately in ticketing systems.
A11: * Perform basic threat intelligence lookups and log analysis to support investigations.
A12: * Follow defined playbooks and assist in fine-tuning alert rules and use cases.
A13: * Support daily health checks on security monitoring tools and systems.
... A28: * Understanding of cybersecurity fundamentals and common attack techniq
A30: skill_name | B30: importance | C30: evidence_text | D30: keep | E30: note
A31: SIEM | B31: required | C31: * Monitor security events and alerts from SIEM tools and other security platforms | D31: Y
A32: Incident Response | B32: required | C32: * Escalate verified incidents to L2/L3 analysts or Incident Response team when necessary | D32: Y
A33: Threat Intelligence | B33: required | C33: * Perform basic threat intelligence lookups and log analysis to support investigations | D33: Y
A34: Log Analysis | B34: required | C34: * Perform basic threat intelligence lookups and log analysis to support investigations | D34: Y
A35: Security Operations (SOC) | B35: required | C35: * Support daily health checks on security monitoring tools and systems | D35: Y
A36: Cybersecurity | B36: required | C36: * Maintain awareness of current cybersecurity threats and trends | D36: Y
A37: Networking | B37: required | C37: * Basic understanding of networking concepts (TCP/IP, DNS, firewalls, etc | D37: Y
A38: Splunk | B38: preferred | C38: Familiarity with SIEM tools (e.g., Splunk, QRadar, LogRhythm). | D38: Y
A39: Linux | B39: required | C39: * Basic knowledge of Windows and Linux operating systems | D39: Y
A40: Documentation | B40: required | C40: Document alerts, investigations, and incident handling actions | D40: Y
A41: NEW: Windows | B41: required | C41: Basic knowledge of Windows and Linux operating systems. | D41: Y
A42: NEW: QRadar | B42: preferred | C42: QRadar | D42: Y
A43: NEW: LogRhythm | B43: preferred | C43: LogRhythm | D43: Y

Sheet JD-CY-0008
A1: JD-CY-0008 | CYBER_ANALYST | Internship for Cyber Security Students - RM2,000 for Top Students (entry)
A2: Read the JD, then go down to the table. Mark every pre-filled row keep = Y (correct, fix the cells if needed) or N (wrong). Add missing skills on the empty rows with keep = Y. Yellow rows still need a Y or N.
A3: Go to the label table
A4: Job description
A5: You will join our [COMPANY] Security team in charge of the overall security posture of the company. As part of SecOps, we overlook the security and threat aspects of [COMPANY] and work hand in hand together with other departments. If you will like to experience how the security team work and consistently update your knowledge on all those new emerging threats, join us on our journey!
A7: Responsibilities
A9: * Testing and implementation of new security-related project. (SIEM / endpoint related)
A10: * Help out with daily monitoring of security solutions in the environment.
A11: * Enhance email phishing exercise for internal staffs.
A12: * Ad hoc assignment.
A14: Requirements
A16: * Candidate must possess or currently pursuing in Degree in computer Science/ IT security or equivalent.
... A19: * Available for duration of 3-6 months.
A21: skill_name | B21: importance | C21: evidence_text | D21: keep | E21: note
A22: SIEM | B22: required | C22: (SIEM / endpoint related) | D22: Y
A23: Monitoring & Observability | B23: required | C23: * Help out with daily monitoring of security solutions in the environment | D23: N
A24: Security Operations (SOC) | B24: required | C24: Help out with daily monitoring of security solutions in the environment. | D24: Y
A25: Cybersecurity | B25: preferred | C25: good understanding in Security and Network related concept | D25: Y
A26: Networking | B26: preferred | C26: good understanding in Security and Network related concept | D26: Y
A27: Self-Motivation | B27: required | C27: Able to work independently and fast learner. | D27: Y
A28: NEW: Security Awareness Training | B28: required | C28: Enhance email phishing exercise for internal staffs. | D28: Y

Sheet JD-CY-0009
A1: JD-CY-0009 | CYBER_ANALYST | IT Intern (entry)
A2: Read the JD, then go down to the table. Mark every pre-filled row keep = Y (correct, fix the cells if needed) or N (wrong). Add missing skills on the empty rows with keep = Y. Yellow rows still need a Y or N.
A3: Go to the label table
A4: Job description
A5: About the role
A7: This is a full-time hybrid role for an IT Intern with a six-month duration, based in Setia Alam. The role offers a combination of on-site and remote work flexibility. The IT Intern will assist in software development, software testing, network administration, perform troubleshooting, and ensure systems' reliability and security. Additionally, the intern will support network security initiatives and provide customer service by addressing IT-related inquiries and concerns.
A9: Key responsibilities
A11: * Assist in software development
A12: * Perform software testing
A13: * Support network administration
A14: * Perform troubleshooting to resolve technical issues
A15: * Ensure systems' reliability and security
... A27: * Hands-on experience with IT systems and networks is a plus
A29: skill_name | B29: importance | C29: evidence_text | D29: keep | E29: note
A30: Problem Solving | B30: required | C30: The IT Intern will assist in software development, software testing, network administration, perform troubleshooting, and ensure systems' reliability and security | D30: Y
A31: Network Security | B31: required | C31: Support network security initiatives | D31: Y
A32: Customer Focus | B32: required | C32: Additionally, the intern will support network security initiatives and provide customer service by addressing IT-related inquiries and concerns | D32: Y
A33: PHP | B33: preferred | C33: * Familiarity with PHP, Java, and Network Security practices to support secure system operations | D33: Y
